
üìä RELAT√ìRIO DE TESTES SWAIF-CONFA
==================================================

üéØ M√âTRICAS GERAIS:
   ‚Ä¢ Taxa de Sucesso: 51.8%
   ‚Ä¢ Total de Testes: 56
   ‚Ä¢ Testes Aprovados: 29
   ‚Ä¢ Testes Falharam: 27
   ‚Ä¢ Dura√ß√£o Total: 60.92s

‚ö° PERFORMANCE:
   ‚Ä¢ Tempo M√©dio por Teste: 1.074s
   ‚Ä¢ Teste Mais R√°pido: 0.000s
   ‚Ä¢ Teste Mais Lento: 59.813s

üìã RESULTADOS DETALHADOS:
   ‚Ä¢ TestAnalisador.test_analisar_dados_completos: ‚ùå FALHOU (0.003s)
     Detalhes: Traceback (most recent call last):
  File "C:\Users\dmene\Documents\LIVHealth\TI\Projetos\swaif-confa\tests\unit\test_analisador.py", line 207, in test_analisar_dados_completos
    resultados = self.analisador.analisar(dados)
                 ^^^^^^^^^^^^^^^^^^^^^^^^
AttributeError: 'Analisador' object has no attribute 'analisar'

   ‚Ä¢ TestAnalisador.test_analisar_dados_vazios: ‚ùå FALHOU (0.003s)
     Detalhes: Traceback (most recent call last):
  File "C:\Users\dmene\Documents\LIVHealth\TI\Projetos\swaif-confa\tests\unit\test_analisador.py", line 180, in test_analisar_dados_vazios
    resultados = self.analisador.analisar(dados_vazios)
                 ^^^^^^^^^^^^^^^^^^^^^^^^
AttributeError: 'Analisador' object has no attribute 'analisar'

   ‚Ä¢ TestAnalisador.test_calcular_totais_faturamento: ‚ùå FALHOU (0.029s)
     Detalhes: Traceback (most recent call last):
  File "C:\Users\dmene\AppData\Roaming\Python\Python313\site-packages\pandas\core\indexes\base.py", line 3812, in get_loc
    return self._engine.get_loc(casted_key)
           ~~~~~~~~~~~~~~~~~~~~^^^^^^^^^^^^
  File "pandas/_libs/index.pyx", line 167, in pandas._libs.index.IndexEngine.get_loc
  File "pandas/_libs/index.pyx", line 196, in pandas._libs.index.IndexEngine.get_loc
  File "pandas/_libs/hashtable_class_helper.pxi", line 7088, in pandas._libs.hashtable.PyObjectHashTable.get_item
  File "pandas/_libs/hashtable_class_helper.pxi", line 7096, in pandas._libs.hashtable.PyObjectHashTable.get_item
KeyError: 'valor_faturado'

The above exception was the direct cause of the following exception:

Traceback (most recent call last):
  File "C:\Users\dmene\Documents\LIVHealth\TI\Projetos\swaif-confa\tests\unit\test_analisador.py", line 117, in test_calcular_totais_faturamento
    resultado = self.analisador.calcular_totais_faturamento(dados)
  File "C:\Users\dmene\Documents\LIVHealth\TI\Projetos\swaif-confa\tests\unit\..\..\src\models\analisador.py", line 44, in calcular_totais_faturamento
    total_c6 = df_c6['valor_faturado'].sum()
               ~~~~~^^^^^^^^^^^^^^^^^^
  File "C:\Users\dmene\AppData\Roaming\Python\Python313\site-packages\pandas\core\frame.py", line 4107, in __getitem__
    indexer = self.columns.get_loc(key)
  File "C:\Users\dmene\AppData\Roaming\Python\Python313\site-packages\pandas\core\indexes\base.py", line 3819, in get_loc
    raise KeyError(key) from err
KeyError: 'valor_faturado'

   ‚Ä¢ TestAnalisador.test_calcular_totais_pagamento: ‚ùå FALHOU (0.002s)
     Detalhes: Traceback (most recent call last):
  File "C:\Users\dmene\AppData\Roaming\Python\Python313\site-packages\pandas\core\indexes\base.py", line 3812, in get_loc
    return self._engine.get_loc(casted_key)
           ~~~~~~~~~~~~~~~~~~~~^^^^^^^^^^^^
  File "pandas/_libs/index.pyx", line 167, in pandas._libs.index.IndexEngine.get_loc
  File "pandas/_libs/index.pyx", line 196, in pandas._libs.index.IndexEngine.get_loc
  File "pandas/_libs/hashtable_class_helper.pxi", line 7088, in pandas._libs.hashtable.PyObjectHashTable.get_item
  File "pandas/_libs/hashtable_class_helper.pxi", line 7096, in pandas._libs.hashtable.PyObjectHashTable.get_item
KeyError: 'status'

The above exception was the direct cause of the following exception:

Traceback (most recent call last):
  File "C:\Users\dmene\Documents\LIVHealth\TI\Projetos\swaif-confa\tests\unit\test_analisador.py", line 136, in test_calcular_totais_pagamento
    resultado = self.analisador.calcular_totais_pagamento(dados)
  File "C:\Users\dmene\Documents\LIVHealth\TI\Projetos\swaif-confa\tests\unit\..\..\src\models\analisador.py", line 94, in calcular_totais_pagamento
    df_c6 = df_c6[df_c6['status'].str.contains('Recebido', na=False)]
                  ~~~~~^^^^^^^^^^
  File "C:\Users\dmene\AppData\Roaming\Python\Python313\site-packages\pandas\core\frame.py", line 4107, in __getitem__
    indexer = self.columns.get_loc(key)
  File "C:\Users\dmene\AppData\Roaming\Python\Python313\site-packages\pandas\core\indexes\base.py", line 3819, in get_loc
    raise KeyError(key) from err
KeyError: 'status'

   ‚Ä¢ TestAnalisador.test_comparar_fontes: ‚ùå FALHOU (0.001s)
     Detalhes: Traceback (most recent call last):
  File "C:\Users\dmene\Documents\LIVHealth\TI\Projetos\swaif-confa\tests\unit\test_analisador.py", line 150, in test_comparar_fontes
    resultado = self.analisador._comparar_fontes(
                ^^^^^^^^^^^^^^^^^^^^^^^^^^^^^^^^
AttributeError: 'Analisador' object has no attribute '_comparar_fontes'

   ‚Ä¢ TestAnalisador.test_comparar_fontes_divisao_por_zero: ‚ùå FALHOU (0.002s)
     Detalhes: Traceback (most recent call last):
  File "C:\Users\dmene\Documents\LIVHealth\TI\Projetos\swaif-confa\tests\unit\test_analisador.py", line 165, in test_comparar_fontes_divisao_por_zero
    resultado = self.analisador._comparar_fontes(
                ^^^^^^^^^^^^^^^^^^^^^^^^^^^^^^^^
AttributeError: 'Analisador' object has no attribute '_comparar_fontes'

   ‚Ä¢ TestAnalisador.test_criar_resultado_analise: ‚ùå FALHOU (0.000s)
     Detalhes: Traceback (most recent call last):
  File "C:\Users\dmene\Documents\LIVHealth\TI\Projetos\swaif-confa\tests\unit\test_analisador.py", line 27, in test_criar_resultado_analise
    resultado = ResultadoAnalise(
        par_fontes=('fonte1', 'fonte2'),
    ...<5 lines>...
        percentual_diferenca=10.0
    )
TypeError: ResultadoAnalise.__init__() got an unexpected keyword argument 'percentual_diferenca'

   ‚Ä¢ TestAnalisador.test_init_analisador: ‚úÖ PASSOU (0.000s)
   ‚Ä¢ TestAnalisador.test_padronizar_valores_c6_faturamento: ‚ùå FALHOU (0.001s)
     Detalhes: Traceback (most recent call last):
  File "C:\Users\dmene\Documents\LIVHealth\TI\Projetos\swaif-confa\tests\unit\test_analisador.py", line 51, in test_padronizar_valores_c6_faturamento
    self.assertEqual(resultado.loc[0, 'valor_venda'], 100.50)
    ~~~~~~~~~~~~~~~~^^^^^^^^^^^^^^^^^^^^^^^^^^^^^^^^^^^^^^^^^
AssertionError: 'R$ 100,50' != 100.5

   ‚Ä¢ TestAnalisador.test_padronizar_valores_c6_pagamento: ‚ùå FALHOU (0.003s)
     Detalhes: Traceback (most recent call last):
  File "C:\Users\dmene\Documents\LIVHealth\TI\Projetos\swaif-confa\tests\unit\test_analisador.py", line 73, in test_padronizar_valores_c6_pagamento
    self.assertEqual(resultado.loc[0, 'descontos'], -10.50)
    ~~~~~~~~~~~~~~~~^^^^^^^^^^^^^^^^^^^^^^^^^^^^^^^^^^^^^^^
AssertionError: np.float64(0.0) != -10.5

   ‚Ä¢ TestAnalisador.test_padronizar_valores_gds: ‚ùå FALHOU (0.002s)
     Detalhes: Traceback (most recent call last):
  File "C:\Users\dmene\Documents\LIVHealth\TI\Projetos\swaif-confa\tests\unit\test_analisador.py", line 86, in test_padronizar_valores_gds
    self.assertEqual(resultado.loc[0, 'valor'], 1500.75)
    ~~~~~~~~~~~~~~~~^^^^^^^^^^^^^^^^^^^^^^^^^^^^^^^^^^^^
AssertionError: np.float64(0.0) != 1500.75

   ‚Ä¢ TestAnalisador.test_padronizar_valores_wab: ‚úÖ PASSOU (0.001s)
   ‚Ä¢ TestConciliacaoController.test_executar_conciliacao_com_dados: ‚ùå FALHOU (0.017s)
     Detalhes: Traceback (most recent call last):
  File "C:\Users\dmene\Documents\LIVHealth\TI\Projetos\swaif-confa\tests\unit\test_controller.py", line 84, in test_executar_conciliacao_com_dados
    self.assertTrue(has_data)
    ~~~~~~~~~~~~~~~^^^^^^^^^^
AssertionError: False is not true

   ‚Ä¢ TestConciliacaoController.test_executar_conciliacao_sem_dados: ‚úÖ PASSOU (0.005s)
   ‚Ä¢ TestConciliacaoController.test_init_controller: ‚úÖ PASSOU (0.001s)
   ‚Ä¢ TestConciliacaoController.test_obter_detalhes_fonte_com_dados: ‚ùå FALHOU (0.006s)
     Detalhes: Traceback (most recent call last):
  File "C:\Users\dmene\Documents\LIVHealth\TI\Projetos\swaif-confa\tests\unit\test_controller.py", line 133, in test_obter_detalhes_fonte_com_dados
    self.assertNotIn('erro', detalhes)
    ~~~~~~~~~~~~~~~~^^^^^^^^^^^^^^^^^^
AssertionError: 'erro' unexpectedly found in {'erro': 'Nenhum dado encontrado para faturamento_c6'}

   ‚Ä¢ TestConciliacaoController.test_obter_detalhes_fonte_inexistente: ‚úÖ PASSOU (0.004s)
   ‚Ä¢ TestConciliacaoController.test_obter_detalhes_fonte_pagamento: ‚ùå FALHOU (0.007s)
     Detalhes: Traceback (most recent call last):
  File "C:\Users\dmene\Documents\LIVHealth\TI\Projetos\swaif-confa\tests\unit\test_controller.py", line 163, in test_obter_detalhes_fonte_pagamento
    self.assertEqual(detalhes['tipo_total'], 'Valor Receb√≠vel')
                     ~~~~~~~~^^^^^^^^^^^^^^
KeyError: 'tipo_total'

   ‚Ä¢ TestConciliacaoController.test_obter_detalhes_fonte_vazia: ‚úÖ PASSOU (0.005s)
   ‚Ä¢ TestConciliacaoController.test_obter_resumo_dados_sem_dados: ‚úÖ PASSOU (0.004s)
   ‚Ä¢ TestConciliacaoController.test_verificar_dados_carregados: ‚úÖ PASSOU (0.002s)
   ‚Ä¢ TestDataLoader.test_carregar_dados_mes_com_arquivos: ‚ùå FALHOU (0.012s)
     Detalhes: Traceback (most recent call last):
  File "C:\Users\dmene\Documents\LIVHealth\TI\Projetos\swaif-confa\tests\unit\test_data_loader.py", line 162, in test_carregar_dados_mes_com_arquivos
    self.assertFalse(resultado['faturamento_c6'].empty)
    ~~~~~~~~~~~~~~~~^^^^^^^^^^^^^^^^^^^^^^^^^^^^^^^^^^^
AssertionError: True is not false

   ‚Ä¢ TestDataLoader.test_carregar_dados_mes_pasta_inexistente: ‚úÖ PASSOU (0.003s)
   ‚Ä¢ TestDataLoader.test_get_pasta_mes: ‚ùå FALHOU (0.001s)
     Detalhes: Traceback (most recent call last):
  File "C:\Users\dmene\Documents\LIVHealth\TI\Projetos\swaif-confa\tests\unit\test_data_loader.py", line 47, in test_get_pasta_mes
    self.assertEqual(result, expected)
    ~~~~~~~~~~~~~~~~^^^^^^^^^^^^^^^^^^
AssertionError: 'julho' != '072025'
- julho
+ 072025


   ‚Ä¢ TestDataLoader.test_init_data_loader: ‚úÖ PASSOU (0.001s)
   ‚Ä¢ TestDataLoader.test_ler_csv_arquivo_inexistente: ‚ùå FALHOU (0.001s)
     Detalhes: Traceback (most recent call last):
  File "C:\Users\dmene\Documents\LIVHealth\TI\Projetos\swaif-confa\tests\unit\test_data_loader.py", line 52, in test_ler_csv_arquivo_inexistente
    resultado = self.data_loader.ler_csv(arquivo_inexistente)
TypeError: DataLoader.ler_csv() missing 1 required positional argument: 'column_mapping'

   ‚Ä¢ TestDataLoader.test_ler_csv_arquivo_valido: ‚ùå FALHOU (0.003s)
     Detalhes: Traceback (most recent call last):
  File "C:\Users\dmene\Documents\LIVHealth\TI\Projetos\swaif-confa\tests\unit\test_data_loader.py", line 67, in test_ler_csv_arquivo_valido
    resultado = self.data_loader.ler_csv(test_csv)
TypeError: DataLoader.ler_csv() missing 1 required positional argument: 'column_mapping'

   ‚Ä¢ TestDataLoader.test_ler_wab_txt_arquivo_inexistente: ‚úÖ PASSOU (0.002s)
   ‚Ä¢ TestDataLoader.test_ler_wab_txt_arquivo_valido: ‚ùå FALHOU (0.010s)
     Detalhes: Traceback (most recent call last):
  File "C:\Users\dmene\Documents\LIVHealth\TI\Projetos\swaif-confa\tests\unit\test_data_loader.py", line 90, in test_ler_wab_txt_arquivo_valido
    self.assertFalse(resultado.empty)
    ~~~~~~~~~~~~~~~~^^^^^^^^^^^^^^^^^
AssertionError: True is not false

   ‚Ä¢ TestDataLoader.test_mapear_colunas_c6_faturamento: ‚ùå FALHOU (0.003s)
     Detalhes: Traceback (most recent call last):
  File "C:\Users\dmene\Documents\LIVHealth\TI\Projetos\swaif-confa\tests\unit\test_data_loader.py", line 103, in test_mapear_colunas_c6_faturamento
    resultado = self.data_loader._mapear_colunas(df_original, 'faturamento_C6')
                ^^^^^^^^^^^^^^^^^^^^^^^^^^^^^^^^
AttributeError: 'DataLoader' object has no attribute '_mapear_colunas'

   ‚Ä¢ TestDataLoader.test_mapear_colunas_fonte_inexistente: ‚ùå FALHOU (0.002s)
     Detalhes: Traceback (most recent call last):
  File "C:\Users\dmene\Documents\LIVHealth\TI\Projetos\swaif-confa\tests\unit\test_data_loader.py", line 113, in test_mapear_colunas_fonte_inexistente
    resultado = self.data_loader._mapear_colunas(df_test, 'fonte_inexistente')
                ^^^^^^^^^^^^^^^^^^^^^^^^^^^^^^^^
AttributeError: 'DataLoader' object has no attribute '_mapear_colunas'

   ‚Ä¢ TestTerminalView.test_exibir_cabecalho: ‚úÖ PASSOU (0.001s)
   ‚Ä¢ TestTerminalView.test_exibir_detalhes_fonte_com_erro: ‚úÖ PASSOU (0.001s)
   ‚Ä¢ TestTerminalView.test_exibir_detalhes_fonte_completo: ‚ùå FALHOU (0.003s)
     Detalhes: Traceback (most recent call last):
  File "C:\Python313\Lib\unittest\mock.py", line 1424, in patched
    return func(*newargs, **newkeywargs)
  File "C:\Users\dmene\Documents\LIVHealth\TI\Projetos\swaif-confa\tests\unit\test_terminal_view.py", line 180, in test_exibir_detalhes_fonte_completo
    self.assertIn("5.500,75", output)  # Total principal formatado
    ~~~~~~~~~~~~~^^^^^^^^^^^^^^^^^^^^
AssertionError: '5.500,75' not found in "========================================================================================================================\n                                    SWAIF-CONFA - SISTEMA DE CONCILIA√á√ÉO FINANCEIRA                                     \n========================================================================================================================\n\nDETALHES DA FONTE: FATURAMENTO_C6 - Julho/2025\n========================================================================================================================\n\nüìä INFORMA√á√ïES GERAIS\n----------------------------------------\nTotal de registros: 25\nTotal de colunas: 3\n\nüí∞==================================================\n   VALOR FATURADO: R$             5,500.75\n=====================================================\n\nüìà ESTAT√çSTICAS\n----------------------------------------\nvalor_venda:\n   Total: R$     5,500.75\n   M√©dia: R$       220.03\n   Min/Max: R$ 50.00 / R$ 800.00\n\nüìã PRIMEIROS REGISTROS\n----------------------------------------\nRegistro 1: {'data_venda': '01/07/2025', 'valor_venda': 100.0, 'cliente': 'Cliente A'}\nRegistro 2: {'data_venda': '02/07/2025', 'valor_venda': 200.0, 'cliente': 'Cliente B'}\n"

   ‚Ä¢ TestTerminalView.test_exibir_erro: ‚úÖ PASSOU (0.000s)
   ‚Ä¢ TestTerminalView.test_exibir_menu_principal: ‚úÖ PASSOU (0.000s)
   ‚Ä¢ TestTerminalView.test_exibir_processando: ‚úÖ PASSOU (0.000s)
   ‚Ä¢ TestTerminalView.test_exibir_resultados_conciliacao: ‚ùå FALHOU (0.001s)
     Detalhes: Traceback (most recent call last):
  File "C:\Python313\Lib\unittest\mock.py", line 1424, in patched
    return func(*newargs, **newkeywargs)
  File "C:\Users\dmene\Documents\LIVHealth\TI\Projetos\swaif-confa\tests\unit\test_terminal_view.py", line 65, in test_exibir_resultados_conciliacao
    ResultadoAnalise(
    ~~~~~~~~~~~~~~~~^
        par_fontes=('faturamento_c6', 'faturamento_gds'),
        ^^^^^^^^^^^^^^^^^^^^^^^^^^^^^^^^^^^^^^^^^^^^^^^^^
    ...<5 lines>...
        percentual_diferenca=10.0
        ^^^^^^^^^^^^^^^^^^^^^^^^^
    ),
    ^
TypeError: ResultadoAnalise.__init__() got an unexpected keyword argument 'percentual_diferenca'

   ‚Ä¢ TestTerminalView.test_exibir_resultados_vazios: ‚ùå FALHOU (0.001s)
     Detalhes: Traceback (most recent call last):
  File "C:\Python313\Lib\unittest\mock.py", line 1424, in patched
    return func(*newargs, **newkeywargs)
  File "C:\Users\dmene\Documents\LIVHealth\TI\Projetos\swaif-confa\tests\unit\test_terminal_view.py", line 101, in test_exibir_resultados_vazios
    self.view.exibir_resultados_conciliacao(resultados, '072025')
    ~~~~~~~~~~~~~~~~~~~~~~~~~~~~~~~~~~~~~~~^^^^^^^^^^^^^^^^^^^^^^
  File "C:\Users\dmene\Documents\LIVHealth\TI\Projetos\swaif-confa\tests\unit\..\..\src\views\terminal_view.py", line 87, in exibir_resultados_conciliacao
    self._exibir_resumo_geral(resultados)
    ~~~~~~~~~~~~~~~~~~~~~~~~~^^^^^^^^^^^^
  File "C:\Users\dmene\Documents\LIVHealth\TI\Projetos\swaif-confa\tests\unit\..\..\src\views\terminal_view.py", line 157, in _exibir_resumo_geral
    print(f"Taxa de conformidade: {((total_analises - total_divergencias) / total_analises * 100):.1f}%")
                                    ~~~~~~~~~~~~~~~~~~~~~~~~~~~~~~~~~~~~~~^~~~~~~~~~~~~~~~
ZeroDivisionError: division by zero

   ‚Ä¢ TestTerminalView.test_exibir_resumo_dados: ‚ùå FALHOU (59.813s)
     Detalhes: Traceback (most recent call last):
  File "C:\Python313\Lib\unittest\mock.py", line 1424, in patched
    return func(*newargs, **newkeywargs)
  File "C:\Users\dmene\Documents\LIVHealth\TI\Projetos\swaif-confa\tests\unit\test_terminal_view.py", line 129, in test_exibir_resumo_dados
    self.assertIn("faturamento_c6", output)
    ~~~~~~~~~~~~~^^^^^^^^^^^^^^^^^^^^^^^^^^
AssertionError: 'faturamento_c6' not found in '========================================================================================================================\n                                    SWAIF-CONFA - SISTEMA DE CONCILIA√á√ÉO FINANCEIRA                                     \n========================================================================================================================\n\nRESUMO DOS DADOS - Julho/2025\n========================================================================================================================\n\nüìä FATURAMENTOS\n--------------------------------------------------\n   C6:     10 registros\n   GDS:     15 registros\n\nüí∞ PAGAMENTOS\n--------------------------------------------------\n   C6:      8 registros\n\nüìã DETALHES T√âCNICOS\n--------------------------------------------------\n\nüî∏ FATURAMENTO_C6\n   Registros: 10\n   Colunas: data_venda, valor_venda, cliente\n\nüî∏ FATURAMENTO_GDS\n   Registros: 15\n   Colunas: data, valor, cliente\n\nüî∏ PAGAMENTO_C6\n   Registros: 8\n   Colunas: data_recebivel, valor_recebivel\n\nPressione ENTER para continuar...'

   ‚Ä¢ TestTerminalView.test_formatar_mes_ano: ‚úÖ PASSOU (0.000s)
   ‚Ä¢ TestTerminalView.test_formatar_mes_ano_invalido: ‚úÖ PASSOU (0.000s)
   ‚Ä¢ TestTerminalView.test_init_terminal_view: ‚úÖ PASSOU (0.000s)
   ‚Ä¢ TestTerminalView.test_solicitar_fonte_invalida: ‚úÖ PASSOU (0.001s)
   ‚Ä¢ TestTerminalView.test_solicitar_fonte_valida: ‚úÖ PASSOU (0.001s)
   ‚Ä¢ TestTerminalView.test_solicitar_mes_ano: ‚úÖ PASSOU (0.000s)
   ‚Ä¢ TestIntegracaoCompleta.test_consistencia_padronizacao_valores: ‚úÖ PASSOU (0.015s)
   ‚Ä¢ TestIntegracaoCompleta.test_fluxo_completo_conciliacao: ‚ùå FALHOU (0.014s)
     Detalhes: Traceback (most recent call last):
  File "C:\Users\dmene\Documents\LIVHealth\TI\Projetos\swaif-confa\tests\integration\test_integration.py", line 107, in test_fluxo_completo_conciliacao
    self.assertIn(par, pares_encontrados)
    ~~~~~~~~~~~~~^^^^^^^^^^^^^^^^^^^^^^^^
AssertionError: ('faturamento_c6', 'faturamento_gds') not found in [('GDS', 'C6'), ('GDS', 'WAB'), ('C6', 'WAB'), ('GDS', 'C6')]

   ‚Ä¢ TestIntegracaoCompleta.test_integracao_data_loader_analisador: ‚ùå FALHOU (0.014s)
     Detalhes: Traceback (most recent call last):
  File "C:\Users\dmene\Documents\LIVHealth\TI\Projetos\swaif-confa\tests\integration\test_integration.py", line 131, in test_integracao_data_loader_analisador
    resultados = analisador.analisar(dados)
                 ^^^^^^^^^^^^^^^^^^^
AttributeError: 'Analisador' object has no attribute 'analisar'

   ‚Ä¢ TestIntegracaoCompleta.test_obter_detalhes_todas_fontes: ‚úÖ PASSOU (0.022s)
   ‚Ä¢ TestIntegracaoCompleta.test_performance_sistema_completo: ‚úÖ PASSOU (0.014s)
   ‚Ä¢ TestIntegracaoCompleta.test_resumo_dados_consistente: ‚ùå FALHOU (0.014s)
     Detalhes: Traceback (most recent call last):
  File "C:\Users\dmene\Documents\LIVHealth\TI\Projetos\swaif-confa\tests\integration\test_integration.py", line 233, in test_resumo_dados_consistente
    self.assertGreater(total_registros, 0)
    ~~~~~~~~~~~~~~~~~~^^^^^^^^^^^^^^^^^^^^
AssertionError: 0 not greater than 0

   ‚Ä¢ TestIntegracaoErros.test_sistema_dados_corrompidos: ‚úÖ PASSOU (0.007s)
   ‚Ä¢ TestIntegracaoErros.test_sistema_sem_dados: ‚úÖ PASSOU (0.006s)
   ‚Ä¢ performance_data_loading: ‚úÖ PASSOU (0.016s)
   ‚Ä¢ performance_processing: ‚úÖ PASSOU (0.063s)

üèÜ CRIT√âRIOS DE APROVA√á√ÉO:
   ‚Ä¢ Taxa de Sucesso M√≠nima: 90% ‚ùå
   ‚Ä¢ Performance Aceit√°vel: <5s total ‚ùå
   ‚Ä¢ Cobertura de Componentes: 100% ‚ùå

‚ö†Ô∏è  SISTEMA PRECISA DE AJUSTES!
